[2025-07-23T00:00:37.328254] [Main execution] Error occurred: DataError: Error during data loading: DataLoader.__init__() got an unexpected keyword argument 'data_root'
Traceback:
Traceback (most recent call last):
  File "C:\Users\fgrv\Dev\CursorProjects\crackseg\src\main.py", line 224, in _load_data
    dataloaders_dict = create_dataloaders_from_config(
                       ^^^^^^^^^^^^^^^^^^^^^^^^^^^^^^^
  File "C:\Users\fgrv\Dev\CursorProjects\crackseg\src\crackseg\data\factory.py", line 694, in create_dataloaders_from_config
    dataloader = create_dataloader(
                 ^^^^^^^^^^^^^^^^^^
  File "C:\Users\fgrv\Dev\CursorProjects\crackseg\src\crackseg\data\dataloader.py", line 635, in create_dataloader
    dataloader_instance = DataLoader(
                          ^^^^^^^^^^^
TypeError: DataLoader.__init__() got an unexpected keyword argument 'data_root'

The above exception was the direct cause of the following exception:

Traceback (most recent call last):
  File "C:\Users\fgrv\Dev\CursorProjects\crackseg\src\main.py", line 689, in main
    train_loader, val_loader = _load_data(cfg)
                               ^^^^^^^^^^^^^^^
  File "C:\Users\fgrv\Dev\CursorProjects\crackseg\src\main.py", line 257, in _load_data
    raise DataError(f"Error during data loading: {str(e)}") from e
crackseg.utils.core.exceptions.DataError: Error during data loading: DataLoader.__init__() got an unexpected keyword argument 'data_root'

--- --- ---
