[2025-07-23T00:27:58.269738] [Main execution] Error occurred: ModelError: Error creating model: Error locating target 'src.model.core.unet.BaseUNet', set env var HYDRA_FULL_ERROR=1 to see chained exception.
full_key: model
Traceback:
Traceback (most recent call last):
  File "C:\Users\fgrv\miniconda3\envs\crackseg\Lib\site-packages\hydra\_internal\utils.py", line 644, in _locate
    obj = getattr(obj, part)
          ^^^^^^^^^^^^^^^^^^
AttributeError: module 'src' has no attribute 'model'

During handling of the above exception, another exception occurred:

Traceback (most recent call last):
  File "C:\Users\fgrv\miniconda3\envs\crackseg\Lib\site-packages\hydra\_internal\utils.py", line 650, in _locate
    obj = import_module(mod)
          ^^^^^^^^^^^^^^^^^^
  File "C:\Users\fgrv\miniconda3\envs\crackseg\Lib\importlib\__init__.py", line 90, in import_module
    return _bootstrap._gcd_import(name[level:], package, level)
           ^^^^^^^^^^^^^^^^^^^^^^^^^^^^^^^^^^^^^^^^^^^^^^^^^^^^
  File "<frozen importlib._bootstrap>", line 1387, in _gcd_import
  File "<frozen importlib._bootstrap>", line 1360, in _find_and_load
  File "<frozen importlib._bootstrap>", line 1324, in _find_and_load_unlocked
ModuleNotFoundError: No module named 'src.model'

The above exception was the direct cause of the following exception:

Traceback (most recent call last):
  File "C:\Users\fgrv\miniconda3\envs\crackseg\Lib\site-packages\hydra\_internal\instantiate\_instantiate2.py", line 134, in _resolve_target
    target = _locate(target)
             ^^^^^^^^^^^^^^^
  File "C:\Users\fgrv\miniconda3\envs\crackseg\Lib\site-packages\hydra\_internal\utils.py", line 653, in _locate
    raise ImportError(
ImportError: Error loading 'src.model.core.unet.BaseUNet':
ModuleNotFoundError("No module named 'src.model'")
Are you sure that 'model' is importable from module 'src'?

The above exception was the direct cause of the following exception:

Traceback (most recent call last):
  File "C:\Users\fgrv\Dev\CursorProjects\crackseg\src\main.py", line 317, in _create_model
    model = hydra.utils.instantiate(cfg.model)
            ^^^^^^^^^^^^^^^^^^^^^^^^^^^^^^^^^^
  File "C:\Users\fgrv\miniconda3\envs\crackseg\Lib\site-packages\hydra\_internal\instantiate\_instantiate2.py", line 226, in instantiate
    return instantiate_node(
           ^^^^^^^^^^^^^^^^^
  File "C:\Users\fgrv\miniconda3\envs\crackseg\Lib\site-packages\hydra\_internal\instantiate\_instantiate2.py", line 333, in instantiate_node
    _target_ = _resolve_target(node.get(_Keys.TARGET), full_key)
               ^^^^^^^^^^^^^^^^^^^^^^^^^^^^^^^^^^^^^^^^^^^^^^^^^
  File "C:\Users\fgrv\miniconda3\envs\crackseg\Lib\site-packages\hydra\_internal\instantiate\_instantiate2.py", line 139, in _resolve_target
    raise InstantiationException(msg) from e
hydra.errors.InstantiationException: Error locating target 'src.model.core.unet.BaseUNet', set env var HYDRA_FULL_ERROR=1 to see chained exception.
full_key: model

The above exception was the direct cause of the following exception:

Traceback (most recent call last):
  File "C:\Users\fgrv\Dev\CursorProjects\crackseg\src\main.py", line 692, in main
    model = _create_model(cfg, device)
            ^^^^^^^^^^^^^^^^^^^^^^^^^^
  File "C:\Users\fgrv\Dev\CursorProjects\crackseg\src\main.py", line 337, in _create_model
    raise ModelError(f"Error creating model: {str(e)}") from e
crackseg.utils.core.exceptions.ModelError: Error creating model: Error locating target 'src.model.core.unet.BaseUNet', set env var HYDRA_FULL_ERROR=1 to see chained exception.
full_key: model

--- --- ---
